Workbook

Sheet Inventario
A1: # | B1: Número de artículo | C1: Descripción | D1: Cantidad acumulada | E1: Valor acumulado | F1: Precio Unitario | G1: Check | H1: Valor Buscado | I1: Diferencia
B2: SPEC-752/230/Q_c | C2: Cosmetic 230 Console + Quad HP + Caliport in crate | D2: 1 | E2: 8530.88 | F2: =+IFERROR(E2/D2,0) -> 8530.88 | H2: =+F2*30 -> 255926.4 | I2: =+E2-H2 -> -247395.52
B3: SPEC-586/110/Q_c | C3: Xcell 110 Console + Quad HP + Caliport in crate | D3: 1 | E3: 8253.95 | F3: =+IFERROR(E3/D3,0) -> 8253.95 | H3: =+F3*100 -> 825395 | I3: =+E3-H3 -> -817141.05
B4: SPEC-752/230/D_c | C4: Cosmetic 230 Console + Dual HP + Caliport in crate | D4: 5 | E4: 40975.54 | F4: =+IFERROR(E4/D4,0) -> 8195.108
B5: SPEC-752/230/S_c | C5: Cosmetic 230 Console + Single HP + Caliport in crate | D5: 2 | E5: 13367.41 | F5: =+IFERROR(E5/D5,0) -> 6683.705 | H5: =+F5*100 -> 668370.5 | I5: =+E5-H5 -> -655003.09
A6: 285 | B6: SPEC-745 | C6: Leaseir SRF Console | D6: 9 | E6: 45743.07 | F6: =+IFERROR(E6/D6,0) -> 5082.5633
A7: 186 | B7: SPEC-1466 | C7: MHR Dual BLEND Handpiece | D7: 1 | E7: 4379.59 | F7: =+IFERROR(E7/D7,0) -> 4379.59 | H7: =+F7*100 -> 437959 | I7: =+E7-H7 -> -433579.41
A8: 222 | B8: SPEC-1393 | C8: Leaseir MHR 230 Aesthetic | D8: 1 | E8: 4235 | F8: =+IFERROR(E8/D8,0) -> 4235
A9: 446 | B9: SPEC-212_c | C9: Stage 6 MHR Xcell - 230 Console, Final Unpacked | D9: 3 | E9: 12465.43 | F9: =+IFERROR(E9/D9,0) -> 4155.1433
B10: SPEC-683_c | C10: Leaseir MHR-230-Aesth-b | D10: 6 | E10: 24811.4 | F10: =+IFERROR(E10/D10,0) -> 4135.2333
A11: 474 | B11: SPEC-1392 | C11: Leaseir MHR 110 Aesthetic | D11: 9 | E11: 36787.39 | F11: =+IFERROR(E11/D11,0) -> 4087.4878 | H11: =100*F11 -> 408748.78 | I11: =+E11-H11 -> -371961.39
B12: SPEC-225_c | C12: Stage 6 MHR Xcell - 110 Console, Final Unpacked | D12: 1 | E12: 4035.88 | F12: =+IFERROR(E12/D12,0) -> 4035.88
B13: SPEC-754/Q_c | C13: Quad HP + Caliport packaged for sale | D13: 1 | E13: 3985.38 | F13: =+IFERROR(E13/D13,0) -> 3985.38
B14: SPEC-711_c | C14: QUAD-Aesth-Blend-b Handpiece | D14: 1 | E14: 3979.82 | F14: =+IFERROR(E14/D14,0) -> 3979.82 | G14: Cantidad
B15: SPEC-685_c | C15: QUAD-Aesth-810-b Handpiece | D15: 8 | E15: 30430.73 | F15: =+IFERROR(E15/D15,0) -> 3803.8412
A16: 477 | B16: SPEC-687_c | C16: Dual-Aesth-810-b Handpiece | D16: 3 | E16: 10563.75 | F16: =+IFERROR(E16/D16,0) -> 3521.25
B17: SPEC-330 | C17: LEASEIR DUAL 810-b Handpiece | D17: 5 | E17: 17501.56 | F17: =+IFERROR(E17/D17,0) -> 3500.312
A18: 113 | B18: SPEC-350 | C18: Monocrom - 1ENSPSTM90-026, 808nm diode+Dual Prism | D18: 29 | E18: 101500 | F18: =+IFERROR(E18/D18,0) -> 3500 | G18: =+VLOOKUP(B18,'[1]Hoja 1'!$B:$H,7,0) -> #N/A
B19: SPEC-1395 | C19: Leaseir Dual Aesthetic Handpiece | D19: 14 | E19: 48849.31 | F19: =+IFERROR(E19/D19,0) -> 3489.2364
A20: 293 | B20: SPEC-1396 | C20: Leaseir Quad Aesthetic Handpiece | D20: 1 | E20: 3413.73 | F20: =+IFERROR(E20/D20,0) -> 3413.73 | G20: =+VLOOKUP(B20,'[1]Hoja 1'!$B:$H,7,0) -> #N/A
A21: 97 | B21: SPEC-91 | C21: LASER DIODE ENSPSTM038 | D21: 18 | E21: 59850 | F21: =+IFERROR(E21/D21,0) -> 3325 | G21: =+VLOOKUP(B21,'[1]Hoja 1'!$B:$H,7,0) -> #N/A
B22: SPEC-93 | C22: LASER DIODE ENSPSTM033 | D22: 5 | E22: 16625 | F22: =+IFERROR(E22/D22,0) -> 3325
B23: SPEC-1441 | C23: Quad LH-M [Quad diode M structure) (diodo quad MHR montado) | D23: 1 | E23: 3267.76 | F23: =+IFERROR(E23/D23,0) -> 3267.76
B24: SPEC-479/110 | C24: LEASEIR MHR LASER SYSTEM 110 CONSOLE | D24: 1 | E24: 3128.86 | F24: =+IFERROR(E24/D24,0) -> 3128.86
B25: SPEC-903 | C25: Monocrom Laser Diode, 20 bars, 810 nm , 200A, 4000W | D25: 20 | E25: 62300 | F25: =+IFERROR(E25/D25,0) -> 3115
A26: 256 | B26: SPEC-1440 | C26: Dual LH-M [Dual diode M structure) (diodo dual MHR montado) | D26: 3 | E26: 9137.42 | F26: =+IFERROR(E26/D26,0) -> 3045.8067 | H26: =150*F26 -> 456871 | I26: =+E26-H26 -> -447733.58
B27: SPEC-736 | C27: Monocrom Laser Diode, 20 bars, 810 nm, 200A, 4000W | D27: 29 | E27: 83820 | F27: =+IFERROR(E27/D27,0) -> 2890.3448
A28: 236 | B28: SPEC-1313 | C28: MHR DS 230V Chiller Cart | D28: 6 | E28: 6661.49 | F28: =+IFERROR(E28/D28,0) -> 1110.2483
A29: 261 | B29: SPEC-1418 | C29: QM7 [1200W / 1500W Modular power supply] | D29: 8 | E29: 7800 | F29: =+IFERROR(E29/D29,0) -> 975
B30: SPEC-1120 | C30: PRJ_501-1-50135_C1 [Generador PCB] | D30: 6 | E30: 5400 | F30: =+IFERROR(E30/D30,0) -> 900
B31: SPEC-1120/DF | C31: PRJ_501-1-50135_C1 [Generador PCB] DEFECTUOSO | D31: 2 | E31: 1800 | F31: =+IFERROR(E31/D31,0) -> 900
A32: 169 | B32: SPEC-1402 | C32: Quad 220V Aesthetic Packaging | D32: 1 | E32: 898.31 | F32: =+IFERROR(E32/D32,0) -> 898.31
A33: 332 | B33: SPEC-118 | C33: Stage 1 MHR Xcell - 230 | D33: 2 | E33: 1266.63 | F33: =+IFERROR(E33/D33,0) -> 633.315
B34: SPEC-104 | C34: Water pump | D34: 290 | E34: 167936.84 | F34: =+IFERROR(E34/D34,0) -> 579.09255
B35: SPEC-98 | C35: Power Supply - Vega Lite 750 | D35: 184 | E35: 94760 | F35: =+IFERROR(E35/D35,0) -> 515
A36: 500 | B36: SPEC-142 | C36: Hailea - HC500A - 230V | D36: 16 | E36: 6880 | F36: =+IFERROR(E36/D36,0) -> 430
A37: 75 | B37: SPEC-146 | C37: Hailea - HC500A - 110V | D37: 19 | E37: 7600 | F37: =+IFERROR(E37/D37,0) -> 400
A38: 307 | B38: SPEC-1293 | C38: PRJ_501-1-50114_B1 [SRF RF PCB] | D38: 13 | E38: 4866.29 | F38: =+IFERROR(E38/D38,0) -> 374.33
B39: SPEC-1483 | C39: MHR Ethernet painted back cover | D39: 2 | E39: 700 | F39: =+IFERROR(E39/D39,0) -> 350
A40: 376 | B40: SPEC-216 | C40: MHR Console Back | D40: 10 | E40: 3400 | F40: =+IFERROR(E40/D40,0) -> 340
...

Sheet Stock en Vuelo
A1: OF | B1: Status OF | C1: Código Artículo | D1: Descripción Artículo | E1: Fecha de Cierre | F1: Coste Emitido | G1: Coste Recibido | H1: Coste Emitido y no Recibido
A2: 202500126 | B2: Liberada | C2: SPEC-685_c | D2: QUAD-Aesth-810-b Handpiece | F2: 1751.34 | G2: 0 | H2: 1751.34 | K2: =+VLOOKUP(C2,Inventario!B:B,1,FALSE) -> SPEC-685_c
A3: 202600088 | B3: Liberada | C3: SPEC-234 | D3: Single HP Calibration Port | F3: 387.86 | G3: 232.71 | H3: 155.15 | K3: =+VLOOKUP(C3,Inventario!B:B,1,FALSE) -> SPEC-234
A4: 202600122 | B4: Liberada | C4: SPEC-745 | D4: Leaseir SRF Console | F4: 25860.52 | G4: 5178.82 | H4: 20681.7 | K4: =+VLOOKUP(C4,Inventario!B:B,1,FALSE) -> SPEC-745
A5: 202600123 | B5: Liberada | C5: SPEC-746 | D5: Leaseir SRF FC Handpiece | F5: 1702.43 | G5: 0 | H5: 1702.43 | K5: =+VLOOKUP(C5,Inventario!B:B,1,FALSE) -> SPEC-746
A6: 202600124 | B6: Liberada | C6: SPEC-748 | D6: Leaseir SRF FS Handpiece | F6: 1526.81 | G6: 0 | H6: 1526.81 | K6: =+VLOOKUP(C6,Inventario!B:B,1,FALSE) -> SPEC-748
A7: 202600125 | B7: Liberada | C7: SPEC-749 | D7: Leaseir SRF BS Handpiece | F7: 1386.29 | G7: 0 | H7: 1386.29 | K7: =+VLOOKUP(C7,Inventario!B:B,1,FALSE) -> SPEC-749
A8: 202600178 | B8: Liberada | C8: SPEC-711_c | D8: QUAD-Aesth-Blend-b Handpiece | F8: 4473.96 | G8: 0 | H8: 4473.96 | K8: =+VLOOKUP(C8,Inventario!B:B,1,FALSE) -> SPEC-711_c
A9: 202600262 | B9: Liberada | C9: SPEC-212_c | D9: Stage 6 MHR Xcell - 230 Console, Final Unpacked | F9: 23910.79 | G9: 12465.43 | H9: 11445.36 | K9: =+VLOOKUP(C9,Inventario!B:B,1,FALSE) -> SPEC-212_c
A10: 202600274 | B10: Liberada | C10: SPEC-1393 | D10: Leaseir MHR 230 Aesthetic | F10: 21270.14 | G10: 8489.71 | H10: 12780.43 | K10: =+VLOOKUP(C10,Inventario!B:B,1,FALSE) -> SPEC-1393
A11: 202600289 | B11: Liberada | C11: SPEC-664 | D11: Leaseir MHR-DS-Aesth-B Console | F11: 16662.71 | G11: 3336.97 | H11: 13325.74 | K11: =+VLOOKUP(C11,Inventario!B:B,1,FALSE) -> #N/A
A12: 202600299 | B12: Liberada | C12: SPEC-232 | D12: Dual HP Calibration Port | F12: 3729.66 | G12: 2163.21 | H12: 1566.45 | K12: =+VLOOKUP(C12,Inventario!B:B,1,FALSE) -> SPEC-232
A13: 202600300 | B13: Liberada | C13: SPEC-226 | D13: Quad HP Calibration Port | F13: 2091.45 | G13: 1840.48 | H13: 250.97 | K13: =+VLOOKUP(C13,Inventario!B:B,1,FALSE) -> SPEC-226
... A26: 202600421 | B26: Liberada | C26: SPEC-1396 | D26: Leaseir Quad Aesthetic Handpiece | F26: 7365.73 | G26: 0 | H26: 7365.73 | K26: =+VLOOKUP(C26,Inventario!B:B,1,FALSE) -> SPEC-1396
A27: 202500127 | C27: SPEC-853_C | D27: Dual-810-b Laserhead, capillary | F27: 33455.23 | G27: 0 | H27: 33455.23 | K27: =+VLOOKUP(C27,Inventario!B:B,1,FALSE) -> #N/A
A28: 202600422 | B28: Liberada | C28: SPEC-687_c | D28: Dual-Aesth-810-b Handpiece | F28: 3496.29 | G28: 0 | H28: 3496.29 | I28: LT | K28: =+VLOOKUP(C28,Inventario!B:B,1,FALSE) -> SPEC-687_c
H31: TOTAL | I31: =+SUM(H2:H28) -> 226619.3
